<sdf version='1.6'>
  <model name='kobuki_standalone'>
    <link name='base_footprint'>
      <pose frame=''>0 0 0 0 -0 0</pose>
      <inertial>
        <pose frame=''>0.009933 1.3e-05 0.010241 0 -0 0</pose>
        <mass>4.82131</mass>
        <inertia>
          <ixx>0.0424129</ixx>
          <ixy>-2.88798e-06</ixy>
          <ixz>2.94309e-06</ixz>
          <iyy>0.0426324</iyy>
          <iyz>-1.24986e-06</iyz>
          <izz>0.0762345</izz>
        </inertia>
      </inertial>
      <collision name='base_footprint_fixed_joint_lump__base_link_collision'>
        <pose frame=''>0 0 0.06969 0 -0 0</pose>
        <geometry>
          <cylinder>
            <length>0.10938</length>
            <radius>0.178</radius>
          </cylinder>
        </geometry>
        <surface>
          <contact>
            <ode/>
          </contact>
          <friction>
            <ode>
              <mu>0.3</mu>
              <mu2>0.3</mu2>
            </ode>
          </friction>
        </surface>
      </collision>
      <collision name='base_footprint_fixed_joint_lump__bumper_link_collision_1_collision_1'>
        <pose frame=''>0 0 0.06969 0 -0 0</pose>
        <geometry>
          <cylinder>
            <length>0.10938</length>
            <radius>0.178</radius>
          </cylinder>
        </geometry>
        <surface>
          <contact>
            <ode/>
          </contact>
          <friction>
            <ode/>
          </friction>
        </surface>
      </collision>
      <collision name='base_footprint_fixed_joint_lump__camera_link_collision_2'>
        <pose frame=''>0.067 0 0.1112 0 -0 0</pose>
        <geometry>
          <box>
            <size>0.012 0.132 0.02</size>
          </box>
        </geometry>
        <surface>
          <contact>
            <ode/>
          </contact>
          <friction>
            <ode/>
          </friction>
        </surface>
      </collision>
      <collision name='base_footprint_fixed_joint_lump__caster_back_link_collision_3'>
        <pose frame=''>-0.135 0 0.0192 -1.5708 0 0</pose>
        <geometry>
          <cylinder>
            <length>0.0176</length>
            <radius>0.017</radius>
          </cylinder>
        </geometry>
        <surface>
          <contact>
            <ode>
              <kp>1e+06</kp>
              <kd>100</kd>
              <max_vel>1</max_vel>
              <min_depth>0.001</min_depth>
            </ode>
          </contact>
          <friction>
            <ode>
              <mu>0</mu>
              <mu2>0</mu2>
            </ode>
          </friction>
        </surface>
      </collision>
      <collision name='base_footprint_fixed_joint_lump__caster_front_link_collision_4'>
        <pose frame=''>0.115 0 0.0172 -1.5708 0 0</pose>
        <geometry>
          <cylinder>
            <length>0.0176</length>
            <radius>0.017</radius>
          </cylinder>
        </geometry>
        <surface>
          <contact>
            <ode>
              <kp>1e+06</kp>
              <kd>100</kd>
              <max_vel>1</max_vel>
              <min_depth>0.001</min_depth>
            </ode>
          </contact>
          <friction>
            <ode>
              <mu>0</mu>
              <mu2>0</mu2>
            </ode>
          </friction>
        </surface>
      </collision>
      <collision name='base_footprint_fixed_joint_lump__base_laser_link_collision_5'>
        <pose frame=''>0.115 0 0.1302 0 -0 0</pose>
        <geometry>
          <box>
            <size>0.1 0.1 0.1</size>
          </box>
        </geometry>
        <surface>
          <contact>
            <ode/>
          </contact>
          <friction>
            <ode/>
          </friction>
        </surface>
      </collision>
      <visual name='base_footprint_fixed_joint_lump__base_link_visual'>
        <pose frame=''>0.001 0 0.06219 0 -0 0</pose>
        <geometry>
          <mesh>
            <scale>1 1 1</scale>
            <uri>model://rrt_exploration_tutorials/launch/includes/meshes/main_body.dae</uri>
          </mesh>
        </geometry>
        <material>
          <script>
            <uri>__default__</uri>
            <name>__default__</name>
          </script>
        </material>
      </visual>
      <visual name='base_footprint_fixed_joint_lump__bumper_link_visual_1'>
        <pose frame=''>0.001 0 0.06219 0 -0 0</pose>
        <geometry>
          <mesh>
            <scale>1 1 1</scale>
            <uri>model://rrt_exploration_tutorials/launch/includes/meshes/main_body.dae</uri>
          </mesh>
        </geometry>
        <material>
          <script>
            <uri>__default__</uri>
            <name>__default__</name>
          </script>
        </material>
      </visual>
      <visual name='base_footprint_fixed_joint_lump__camera_link_visual_2'>
        <pose frame=''>0.064 -0.065 0.1042 1.57 -0 1.57</pose>
        <geometry>
          <mesh>
            <scale>1 1 1</scale>
            <uri>model://rrt_exploration_tutorials/launch/includes/meshes/r200.dae</uri>
          </mesh>
        </geometry>
        <material>
          <script>
            <uri>__default__</uri>
            <name>__default__</name>
          </script>
        </material>
      </visual>
      <visual name='base_footprint_fixed_joint_lump__base_laser_link_visual_3'>
        <pose frame=''>0.115 0 0.1302 0 -0 0</pose>
        <geometry>
          <mesh>
            <scale>1 1 1</scale>
            <uri>model://rrt_exploration_tutorials/launch/includes/meshes/hokuyo.dae</uri>
          </mesh>
        </geometry>
        <material>
          <script>
            <uri>__default__</uri>
            <name>__default__</name>
          </script>
        </material>
      </visual>
      <velocity_decay/>
      <sensor name='bumpers' type='contact'>
        <always_on>1</always_on>
        <update_rate>50</update_rate>
        <visualize>1</visualize>
        <contact>
          <collision>base_footprint_collision_base_link_collision</collision>
          <topic>__default_topic__</topic>
        </contact>
        <pose frame=''>0 0 0.0102 0 -0 0</pose>
      </sensor>
      <velocity_decay/>
      <sensor name='bumpers' type='contact'>
        <always_on>1</always_on>
        <update_rate>50</update_rate>
        <visualize>1</visualize>
        <contact>
          <collision>base_footprint_fixed_joint_lump__bumper_link_collision_1</collision>
          <topic>__default_topic__</topic>
        </contact>
        <plugin name='gazebo_ros_bumper_controller' filename='libgazebo_ros_bumper.so'>
          <updateRate>50.0</updateRate>
          <bumperTopicName>bumper</bumperTopicName>
          <frameName>base_link</frameName>
        </plugin>
        <pose frame=''>0 0 0.0102 0 -0 0</pose>
      </sensor>
      <velocity_decay/>
      <sensor name='rgbcamera' type='camera'>
        <update_rate>30</update_rate>
        <camera name='head'>
          <horizontal_fov>1.4</horizontal_fov>
          <image>
            <width>642</width>
            <height>362</height>
            <format>R8G8B8</format>
          </image>
          <clip>
            <near>0.02</near>
            <far>300</far>
          </clip>
          <noise>
            <type>gaussian</type>
            <mean>0</mean>
            <stddev>0.007</stddev>
          </noise>
        </camera>
        <plugin name='camera_controller' filename='libgazebo_ros_camera.so'>
          <alwaysOn>true</alwaysOn>
          <updateRate>0.0</updateRate>
          <cameraName>rgbcamera</cameraName>
          <imageTopicName>image_raw</imageTopicName>
          <cameraInfoTopicName>camera_info</cameraInfoTopicName>
          <frameName>camera_link</frameName>
          <hackBaseline>0.07</hackBaseline>
          <distortionK1>0.0</distortionK1>
          <distortionK2>0.0</distortionK2>
          <distortionK3>0.0</distortionK3>
          <distortionT1>0.0</distortionT1>
          <distortionT2>0.0</distortionT2>
        </plugin>
        <pose frame=''>0.064 -0.065 0.1042 0 -0 0</pose>
      </sensor>
      <velocity_decay/>
      <velocity_decay/>
      <velocity_decay/>
      <sensor name='cliff_sensor_front' type='ray'>
        <always_on>1</always_on>
        <update_rate>50</update_rate>
        <visualize>1</visualize>
        <ray>
          <scan>
            <horizontal>
              <samples>50</samples>
              <resolution>1</resolution>
              <min_angle>-0.0436</min_angle>
              <max_angle>0.0436</max_angle>
            </horizontal>
          </scan>
          <range>
            <min>0.01</min>
            <max>0.15</max>
            <resolution>1</resolution>
          </range>
        </ray>
        <pose frame=''>0.156 0 0.0316 3.14159 1.57079 3.14159</pose>
      </sensor>
      <velocity_decay/>
      <sensor name='cliff_sensor_left' type='ray'>
        <always_on>1</always_on>
        <update_rate>50</update_rate>
        <visualize>1</visualize>
        <ray>
          <scan>
            <horizontal>
              <samples>50</samples>
              <resolution>1</resolution>
              <min_angle>-0.0436</min_angle>
              <max_angle>0.0436</max_angle>
            </horizontal>
          </scan>
          <range>
            <min>0.01</min>
            <max>0.15</max>
            <resolution>1</resolution>
          </range>
        </ray>
        <pose frame=''>0.08734 0.13601 0.0316 3.14159 1.57079 3.14159</pose>
      </sensor>
      <velocity_decay/>
      <sensor name='cliff_sensor_right' type='ray'>
        <always_on>1</always_on>
        <update_rate>50</update_rate>
        <visualize>1</visualize>
        <ray>
          <scan>
            <horizontal>
              <samples>50</samples>
              <resolution>1</resolution>
              <min_angle>-0.0436</min_angle>
              <max_angle>0.0436</max_angle>
            </horizontal>
          </scan>
          <range>
            <min>0.01</min>
            <max>0.15</max>
            <resolution>1</resolution>
          </range>
        </ray>
        <pose frame=''>0.085 -0.13601 0.0316 3.14159 1.57079 3.14159</pose>
      </sensor>
      <velocity_decay/>
      <sensor name='imu' type='imu'>
        <always_on>1</always_on>
        <update_rate>50</update_rate>
        <visualize>0</visualize>
        <imu>
          <angular_velocity>
            <x>
              <noise type='gaussian'>
                <mean>0</mean>
                <stddev>1.96e-06</stddev>
                <bias_mean>0</bias_mean>
                <bias_stddev>0</bias_stddev>
              </noise>
            </x>
            <y>
              <noise type='gaussian'>
                <mean>0</mean>
                <stddev>1.96e-06</stddev>
                <bias_mean>0</bias_mean>
                <bias_stddev>0</bias_stddev>
              </noise>
            </y>
            <z>
              <noise type='gaussian'>
                <mean>0</mean>
                <stddev>1.96e-06</stddev>
                <bias_mean>0</bias_mean>
                <bias_stddev>0</bias_stddev>
              </noise>
            </z>
          </angular_velocity>
          <linear_acceleration>
            <x>
              <noise type='gaussian'>
                <mean>0</mean>
                <stddev>0.017</stddev>
                <bias_mean>0.1</bias_mean>
                <bias_stddev>0.001</bias_stddev>
              </noise>
            </x>
            <y>
              <noise type='gaussian'>
                <mean>0</mean>
                <stddev>0.017</stddev>
                <bias_mean>0.1</bias_mean>
                <bias_stddev>0.001</bias_stddev>
              </noise>
            </y>
            <z>
              <noise type='gaussian'>
                <mean>0</mean>
                <stddev>0.017</stddev>
                <bias_mean>0.1</bias_mean>
                <bias_stddev>0.001</bias_stddev>
              </noise>
            </z>
          </linear_acceleration>
        </imu>
        <pose frame=''>0.056 0.062 0.0304 0 -0 0</pose>
      </sensor>
      <gravity>1</gravity>
      <velocity_decay/>
      <self_collide>0</self_collide>
      <sensor name='head_hokuyo_sensor' type='ray'>
        <visualize>1</visualize>
        <update_rate>40</update_rate>
        <ray>
          <scan>
            <horizontal>
              <samples>720</samples>
              <resolution>1</resolution>
              <min_angle>-1.5708</min_angle>
              <max_angle>1.5708</max_angle>
            </horizontal>
          </scan>
          <range>
            <min>0.1</min>
            <max>60</max>
            <resolution>0.01</resolution>
          </range>
          <noise>
            <type>gaussian</type>
            <mean>0</mean>
            <stddev>0.01</stddev>
          </noise>
        </ray>
        <plugin name='gazebo_ros_head_hokuyo_controller' filename='libgazebo_ros_laser.so'>
          <topicName>base_scan</topicName>
          <frameName>base_laser_link</frameName>
        </plugin>
        <pose frame=''>0.115 0 0.1302 0 -0 0</pose>
      </sensor>
    </link>
    <link name='wheel_left_link'>
      <pose frame=''>0 0.115 0.0352 -1.5708 0 0</pose>
      <inertial>
        <pose frame=''>0 0 0 0 -0 0</pose>
        <mass>0.01</mass>
        <inertia>
          <ixx>0.001</ixx>
          <ixy>0</ixy>
          <ixz>0</ixz>
          <iyy>0.001</iyy>
          <iyz>0</iyz>
          <izz>0.001</izz>
        </inertia>
      </inertial>
      <collision name='wheel_left_link_collision'>
        <pose frame=''>0 0 0 0 -0 0</pose>
        <geometry>
          <cylinder>
            <length>0.0206</length>
            <radius>0.0352</radius>
          </cylinder>
        </geometry>
        <surface>
          <contact>
            <ode>
              <kp>1e+06</kp>
              <kd>100</kd>
              <max_vel>1</max_vel>
              <min_depth>0.001</min_depth>
            </ode>
          </contact>
          <friction>
            <ode>
              <mu>1</mu>
              <mu2>1</mu2>
            </ode>
          </friction>
        </surface>
      </collision>
      <visual name='wheel_left_link_visual'>
        <pose frame=''>0 0 0 0 -0 0</pose>
        <geometry>
          <mesh>
            <scale>1 1 1</scale>
            <uri>model://rrt_exploration_tutorials/launch/includes/meshes/wheel.dae</uri>
          </mesh>
        </geometry>
        <material>
          <script>
            <uri>__default__</uri>
            <name>__default__</name>
          </script>
        </material>
      </visual>
      <gravity>1</gravity>
      <velocity_decay/>
      <self_collide>0</self_collide>
    </link>
    <joint name='wheel_left_joint' type='revolute'>
      <child>wheel_left_link</child>
      <parent>base_footprint</parent>
      <axis>
        <xyz>0 1 0</xyz>
        <limit>
          <lower>-1e+16</lower>
          <upper>1e+16</upper>
        </limit>
        <dynamics>
          <spring_reference>0</spring_reference>
          <spring_stiffness>0</spring_stiffness>
        </dynamics>
        <use_parent_model_frame>1</use_parent_model_frame>
      </axis>
    </joint>
    <link name='wheel_right_link'>
      <pose frame=''>0 -0.115 0.0352 -1.5708 0 0</pose>
      <inertial>
        <pose frame=''>0 0 0 0 -0 0</pose>
        <mass>0.01</mass>
        <inertia>
          <ixx>0.001</ixx>
          <ixy>0</ixy>
          <ixz>0</ixz>
          <iyy>0.001</iyy>
          <iyz>0</iyz>
          <izz>0.001</izz>
        </inertia>
      </inertial>
      <collision name='wheel_right_link_collision'>
        <pose frame=''>0 0 0 0 -0 0</pose>
        <geometry>
          <cylinder>
            <length>0.0206</length>
            <radius>0.035</radius>
          </cylinder>
        </geometry>
        <surface>
          <contact>
            <ode>
              <kp>1e+06</kp>
              <kd>100</kd>
              <max_vel>1</max_vel>
              <min_depth>0.001</min_depth>
            </ode>
          </contact>
          <friction>
            <ode>
              <mu>1</mu>
              <mu2>1</mu2>
            </ode>
          </friction>
        </surface>
      </collision>
      <visual name='wheel_right_link_visual'>
        <pose frame=''>0 0 0 0 -0 0</pose>
        <geometry>
          <mesh>
            <scale>1 1 1</scale>
            <uri>model://rrt_exploration_tutorials/launch/includes/meshes/wheel.dae</uri>
          </mesh>
        </geometry>
        <material>
          <script>
            <uri>__default__</uri>
            <name>__default__</name>
          </script>
        </material>
      </visual>
      <gravity>1</gravity>
      <velocity_decay/>
      <self_collide>0</self_collide>
    </link>
    <joint name='wheel_right_joint' type='revolute'>
      <child>wheel_right_link</child>
      <parent>base_footprint</parent>
      <axis>
        <xyz>0 1 0</xyz>
        <limit>
          <lower>-1e+16</lower>
          <upper>1e+16</upper>
        </limit>
        <dynamics>
          <spring_reference>0</spring_reference>
          <spring_stiffness>0</spring_stiffness>
        </dynamics>
        <use_parent_model_frame>1</use_parent_model_frame>
      </axis>
    </joint>
    <static>0</static>
    <plugin name='kobuki_controller' filename='libgazebo_ros_kobuki.so'>
      <publish_tf>1</publish_tf>
      <left_wheel_joint_name>wheel_left_joint</left_wheel_joint_name>
      <right_wheel_joint_name>wheel_right_joint</right_wheel_joint_name>
      <wheel_separation>.230</wheel_separation>
      <wheel_diameter>0.070</wheel_diameter>
      <torque>1.0</torque>
      <velocity_command_timeout>0.6</velocity_command_timeout>
      <cliff_sensor_left_name>cliff_sensor_left</cliff_sensor_left_name>
      <cliff_sensor_center_name>cliff_sensor_front</cliff_sensor_center_name>
      <cliff_sensor_right_name>cliff_sensor_right</cliff_sensor_right_name>
      <cliff_detection_threshold>0.04</cliff_detection_threshold>
      <bumper_name>bumpers</bumper_name>
      <imu_name>imu</imu_name>
    </plugin>
  </model>
</sdf>
