<?xml version="1.0" ?>
<!-- =================================================================================== -->
<!-- |    This document was autogenerated by xacro from kobuki_standalone.urdf.xacro   | -->
<!-- |    EDITING THIS FILE BY HAND IS NOT RECOMMENDED                                 | -->
<!-- =================================================================================== -->
<robot name="kobuki_standalone" xmlns:controller="http://playerstage.sourceforge.net/gazebo/xmlschema/#controller" xmlns:interface="http://playerstage.sourceforge.net/gazebo/xmlschema/#interface" xmlns:sensor="http://playerstage.sourceforge.net/gazebo/xmlschema/#sensor" xmlns:xacro="http://ros.org/wiki/xacro">
  <link name="base_footprint"/>
  <!--
       Base link is set at the bottom of the base mould.
       This is done to be compatible with the way base link
       was configured for turtlebot 1. Refer to
       
       https://github.com/turtlebot/turtlebot/issues/40
       
       To put the base link at the more oft used wheel
       axis, set the z-distance from the base_footprint
       to 0.352.
      -->
  <joint name="base_joint" type="fixed">
    <origin rpy="0 0 0" xyz="0 0 0.0102"/>
    <parent link="base_footprint"/>
    <child link="base_link"/>
  </joint>
  <link name="base_link">
    <visual>
      <geometry>
        <!-- new mesh -->
        <mesh filename="package://rrt_exploration_tutorials/launch/includes/meshes/main_body.dae"/>
      </geometry>
      <origin rpy="0 0 0" xyz="0.001 0 0.05199"/>
    </visual>
    <collision>
      <geometry>
        <cylinder length="0.10938" radius="0.178"/>
      </geometry>
      <surface>
        <contact>
          <ode/>
        </contact>
        <friction>
          <ode/>
        </friction>
      </surface>
      <origin rpy="0 0 0" xyz="0.0 0 0.05949"/>
    </collision>
    <inertial>
      <!-- COM experimentally determined -->
      <origin xyz="0.01 0 0"/>
      <mass value="2.4"/>
      <!-- 2.4/2.6 kg for small/big battery pack -->
      <!-- Kobuki's inertia tensor is approximated by a cylinder with homogeneous mass distribution
             More details: http://en.wikipedia.org/wiki/List_of_moment_of_inertia_tensors
             m = 2.4 kg; h = 0.09 m; r = 0.175 m
             ixx = 1/12 * m * (3 * r^2 + h^2)
             iyy = 1/12 * m * (3 * r^2 + h^2)
             izz = 1/2 * m * r^2 
          -->
      <inertia ixx="0.019995" ixy="0.0" ixz="0.0" iyy="0.019995" iyz="0.0" izz="0.03675"/>
    </inertial>
  </link>
  <joint name="wheel_left_joint" type="continuous">
    <parent link="base_link"/>
    <child link="wheel_left_link"/>
    <origin rpy="-1.57079632679 0 0" xyz="0.00 0.115 0.0250"/>
    <axis xyz="0 0 1"/>
  </joint>
  <link name="wheel_left_link">
    <visual>
      <geometry>
        <mesh filename="package://rrt_exploration_tutorials/launch/includes/meshes/wheel.dae"/>
      </geometry>
      <origin rpy="0 0 0" xyz="0 0 0"/>
    </visual>
    <collision>
      <geometry>
        <cylinder length="0.0206" radius="0.0352"/>
      </geometry>
      <origin rpy="0 0 0" xyz="0 0 0"/>
    </collision>
    <inertial>
      <mass value="0.01"/>
      <origin xyz="0 0 0"/>
      <inertia ixx="0.001" ixy="0.0" ixz="0.0" iyy="0.001" iyz="0.0" izz="0.001"/>
    </inertial>
  </link>
  <joint name="wheel_right_joint" type="continuous">
    <parent link="base_link"/>
    <child link="wheel_right_link"/>
    <origin rpy="-1.57079632679 0 0" xyz="0.00 -0.115 0.0250"/>
    <axis xyz="0 0 1"/>
  </joint>
  <link name="wheel_right_link">
    <visual>
      <geometry>
        <mesh filename="package://rrt_exploration_tutorials/launch/includes/meshes/wheel.dae"/>
      </geometry>
      <origin rpy="0 0 0" xyz="0 0 0"/>
    </visual>
    <collision>
      <geometry>
        <cylinder length="0.0206" radius="0.0350"/>
      </geometry>
      <origin rpy="0 0 0" xyz="0 0 0"/>
    </collision>
    <inertial>
      <mass value="0.01"/>
      <origin xyz="0 0 0"/>
      <inertia ixx="0.001" ixy="0.0" ixz="0.0" iyy="0.001" iyz="0.0" izz="0.001"/>
    </inertial>
  </link>
  <joint name="caster_front_joint" type="fixed">
    <parent link="base_link"/>
    <child link="caster_front_link"/>
    <origin rpy="-1.57079632679 0 0" xyz="0.115 0.0 0.007"/>
  </joint>
  <link name="caster_front_link">
    <collision>
      <geometry>
        <cylinder length="0.0176" radius="0.017"/>
      </geometry>
      <origin rpy="0 0 0" xyz="0 0 0"/>
    </collision>
    <inertial>
      <mass value="0.01"/>
      <origin xyz="0 0 0"/>
      <inertia ixx="0.001" ixy="0.0" ixz="0.0" iyy="0.001" iyz="0.0" izz="0.001"/>
    </inertial>
  </link>
  <joint name="caster_back_joint" type="fixed">
    <parent link="base_link"/>
    <child link="caster_back_link"/>
    <origin rpy="-1.57079632679 0 0" xyz="-0.135 0.0 0.009"/>
  </joint>
  <link name="caster_back_link">
    <collision>
      <geometry>
        <cylinder length="0.0176" radius="0.017"/>
      </geometry>
      <origin rpy="0 0 0" xyz="0 0 0"/>
    </collision>
    <inertial>
      <mass value="0.01"/>
      <origin xyz="0 0 0"/>
      <inertia ixx="0.001" ixy="0.0" ixz="0.0" iyy="0.001" iyz="0.0" izz="0.001"/>
    </inertial>
  </link>
  <!-- Kobuki's sensors -->
  <joint name="gyro_joint" type="fixed">
    <axis xyz="0 1 0"/>
    <origin rpy="0 0 0" xyz="0.056 0.062 0.0202"/>
    <parent link="base_link"/>
    <child link="gyro_link"/>
  </joint>
  <link name="gyro_link">
    <inertial>
      <mass value="0.001"/>
      <origin rpy="0 0 0" xyz="0 0 0"/>
      <inertia ixx="0.0001" ixy="0" ixz="0" iyy="0.000001" iyz="0" izz="0.0001"/>
    </inertial>
  </link>
  <joint name="cliff_sensor_left_joint" type="fixed">
    <origin rpy="0 1.57079632679 0" xyz="0.08734 0.13601 0.0214"/>
    <parent link="base_link"/>
    <child link="cliff_sensor_left_link"/>
  </joint>
  <link name="cliff_sensor_left_link">
    <inertial>
      <mass value="0.0001"/>
      <origin xyz="0 0 0"/>
      <inertia ixx="0.0001" ixy="0.0" ixz="0.0" iyy="0.0001" iyz="0.0" izz="0.0001"/>
    </inertial>
  </link>
  <joint name="cliff_sensor_right_joint" type="fixed">
    <origin rpy="0 1.57079632679 0" xyz="0.085 -0.13601 0.0214"/>
    <parent link="base_link"/>
    <child link="cliff_sensor_right_link"/>
  </joint>
  <link name="cliff_sensor_right_link">
    <inertial>
      <mass value="0.0001"/>
      <origin xyz="0 0 0"/>
      <inertia ixx="0.0001" ixy="0.0" ixz="0.0" iyy="0.0001" iyz="0.0" izz="0.0001"/>
    </inertial>
  </link>
  <joint name="cliff_sensor_front_joint" type="fixed">
    <origin rpy="0 1.57079632679 0" xyz="0.156 0.00 0.0214"/>
    <parent link="base_link"/>
    <child link="cliff_sensor_front_link"/>
  </joint>
  <link name="cliff_sensor_front_link">
    <inertial>
      <mass value="0.0001"/>
      <origin xyz="0 0 0"/>
      <inertia ixx="0.0001" ixy="0.0" ixz="0.0" iyy="0.0001" iyz="0.0" izz="0.0001"/>
    </inertial>
  </link>
  <joint name="laser_joint" type="fixed">
    <origin rpy="0 0 0" xyz=".115 0 0.12"/>
    <parent link="base_link"/>
    <child link="base_laser_link"/>
  </joint>
  <link name="base_laser_link">
    <collision>
      <origin rpy="0 0 0" xyz="0 0 0"/>
      <geometry>
        <box size="0.1 0.1 0.1"/>
      </geometry>
    </collision>
    <visual>
      <origin rpy="0 0 0" xyz="0 0 0"/>
      <geometry>
        <mesh filename="package://rrt_exploration_tutorials/launch/includes/meshes/hokuyo.dae"/>
      </geometry>
    </visual>
    <inertial>
      <mass value="1e-5"/>
      <origin rpy="0 0 0" xyz="0 0 1"/>
      <inertia ixx="1e-6" ixy="0" ixz="0" iyy="1e-6" iyz="0" izz="1e-6"/>
    </inertial>
  </link>
  <joint name="camera_joint" type="fixed">
    <origin rpy="0 0 0" xyz="0.064 -0.065 0.094"/>
    <parent link="base_link"/>
    <child link="camera_link"/>
  </joint>
  <link name="camera_link">
    <visual>
      <origin rpy="1.57 0 1.57" xyz="0 0 0"/>
      <geometry>
        <mesh filename="package://rrt_exploration_tutorials/launch/includes/meshes/r200.dae"/>
      </geometry>
    </visual>
    <collision>
      <origin rpy="0 0 0" xyz="0.003 0.065 0.007"/>
      <geometry>
        <box size="0.012 0.132 0.020"/>
      </geometry>
    </collision>
  </link>
  <joint name="bumper_joint" type="fixed">
    <origin rpy="0 0 0" xyz="0 0 0"/>
    <parent link="base_link"/>
    <child link="bumper_link"/>
  </joint>
  <link name="bumper_link">
    <visual>
      <geometry>
        <!-- new mesh -->
        <mesh filename="package://rrt_exploration_tutorials/launch/includes/meshes/main_body.dae"/>
      </geometry>
      <origin rpy="0 0 0" xyz="0.001 0 0.05199"/>
    </visual>
    <collision name="base_footprint_fixed_joint_lump__bumper_link_collision_1">
      <origin rpy="0 0 0" xyz="0.0 0 0.05949"/>
      <geometry>
        <cylinder length="0.10938" radius="0.178"/>
      </geometry>
      <surface>
        <contact>
          <ode/>
        </contact>
        <friction>
          <ode/>
        </friction>
      </surface>
    </collision>
    <inertial>
      <mass value="2.4"/>
      <origin rpy="0 0 0" xyz="0.01 0 0"/>
      <inertia ixx="0.019995" ixy="0.0" ixz="0.0" iyy="0.019995" iyz="0.0" izz="0.03675"/>
    </inertial>
  </link>
  <gazebo reference="wheel_left_link">
    <mu1>1.0</mu1>
    <mu2>1.0</mu2>
    <kp>1000000.0</kp>
    <kd>100.0</kd>
    <minDepth>0.001</minDepth>
    <maxVel>1.0</maxVel>
  </gazebo>
  <gazebo reference="wheel_right_link">
    <mu1>1.0</mu1>
    <mu2>1.0</mu2>
    <kp>1000000.0</kp>
    <kd>100.0</kd>
    <minDepth>0.001</minDepth>
    <maxVel>1.0</maxVel>
  </gazebo>
  <gazebo reference="caster_front_link">
    <mu1>0.0</mu1>
    <mu2>0.0</mu2>
    <kp>1000000.0</kp>
    <kd>100.0</kd>
    <minDepth>0.001</minDepth>
    <maxVel>1.0</maxVel>
  </gazebo>
  <gazebo reference="caster_back_link">
    <mu1>0.0</mu1>
    <mu2>0.0</mu2>
    <kp>1000000.0</kp>
    <kd>100.0</kd>
    <minDepth>0.001</minDepth>
    <maxVel>1.0</maxVel>
  </gazebo>
  <gazebo reference="base_link">
    <mu1>0.3</mu1>
    <mu2>0.3</mu2>
    <sensor name="bumpers" type="contact">
      <always_on>true</always_on>
      <update_rate>50.0</update_rate>
      <visualize>true</visualize>
      <contact>
        <collision>base_footprint_collision_base_link_collision</collision>
      </contact>
    </sensor>
  </gazebo>
  <gazebo reference="bumper_link">
    <sensor name="bumpers" type="contact">
      <always_on>true</always_on>
      <update_rate>50.0</update_rate>
      <visualize>true</visualize>
      <contact>
        <collision>base_footprint_fixed_joint_lump__bumper_link_collision_1</collision>
      </contact>
      <plugin filename="libgazebo_ros_bumper.so" name="gazebo_ros_bumper_controller">
        <updateRate>50.0</updateRate>
        <bumperTopicName>bumper</bumperTopicName>
        <frameName>base_link</frameName>
      </plugin>
    </sensor>
  </gazebo>
  <gazebo reference="cliff_sensor_left_link">
    <sensor name="cliff_sensor_left" type="ray">
      <always_on>true</always_on>
      <update_rate>50</update_rate>
      <visualize>true</visualize>
      <ray>
        <scan>
          <horizontal>
            <samples>50</samples>
            <resolution>1.0</resolution>
            <min_angle>-0.0436</min_angle>
            <!-- -2.5 degree -->
            <max_angle>0.0436</max_angle>
            <!-- 2.5 degree -->
          </horizontal>
          <!--            Can't use vertical rays until this bug is resolved: -->
          <!--            https://bitbucket.org/osrf/gazebo/issue/509/vertical-sensor-doesnt-works -->
          <!-- 	          <vertical> -->
          <!-- 	            <samples>50</samples> -->
          <!-- 	            <resolution>1.0</resolution> -->
          <!-- 	            <min_angle>-0.0436</min_angle>  -2.5 degree -->
          <!-- 	            <max_angle>0.0436</max_angle> 2.5 degree -->
          <!-- 	          </vertical> -->
        </scan>
        <range>
          <min>0.01</min>
          <max>0.15</max>
          <resolution>1.0</resolution>
        </range>
      </ray>
    </sensor>
  </gazebo>
  <gazebo reference="cliff_sensor_right_link">
    <sensor name="cliff_sensor_right" type="ray">
      <always_on>true</always_on>
      <update_rate>50</update_rate>
      <visualize>true</visualize>
      <ray>
        <scan>
          <horizontal>
            <samples>50</samples>
            <resolution>1.0</resolution>
            <min_angle>-0.0436</min_angle>
            <!-- -2.5 degree -->
            <max_angle>0.0436</max_angle>
            <!-- 2.5 degree -->
          </horizontal>
          <!--            Can't use vertical rays until this bug is resolved: -->
          <!--            https://bitbucket.org/osrf/gazebo/issue/509/vertical-sensor-doesnt-works -->
          <!-- 	          <vertical> -->
          <!-- 	            <samples>50</samples> -->
          <!-- 	            <resolution>1.0</resolution> -->
          <!-- 	            <min_angle>-0.0436</min_angle>  -2.5 degree -->
          <!-- 	            <max_angle>0.0436</max_angle> 2.5 degree -->
          <!-- 	          </vertical> -->
        </scan>
        <range>
          <min>0.01</min>
          <max>0.15</max>
          <resolution>1.0</resolution>
        </range>
      </ray>
    </sensor>
  </gazebo>
  <gazebo reference="cliff_sensor_front_link">
    <sensor name="cliff_sensor_front" type="ray">
      <always_on>true</always_on>
      <update_rate>50</update_rate>
      <visualize>true</visualize>
      <ray>
        <scan>
          <horizontal>
            <samples>50</samples>
            <resolution>1.0</resolution>
            <min_angle>-0.0436</min_angle>
            <!-- -2.5 degree -->
            <max_angle>0.0436</max_angle>
            <!-- 2.5 degree -->
          </horizontal>
          <!-- 	          Can't use vertical rays until this bug is resolved: -->
          <!--            https://bitbucket.org/osrf/gazebo/issue/509/vertical-sensor-doesnt-works -->
          <!-- 	          <vertical> -->
          <!-- 	            <samples>50</samples> -->
          <!-- 	            <resolution>1.0</resolution> -->
          <!-- 	            <min_angle>-0.0436</min_angle>  -2.5 degree -->
          <!-- 	            <max_angle>0.0436</max_angle> 2.5 degree -->
          <!-- 	          </vertical> -->
        </scan>
        <range>
          <min>0.01</min>
          <max>0.15</max>
          <resolution>1.0</resolution>
        </range>
      </ray>
    </sensor>
  </gazebo>
  <gazebo reference="gyro_link">
    <sensor name="imu" type="imu">
      <always_on>true</always_on>
      <update_rate>50</update_rate>
      <visualize>false</visualize>
      <imu>
        <noise>
          <type>gaussian</type>
          <rate>
            <mean>0.0</mean>
            <stddev>1.96e-06</stddev>
            <!-- 0.25 x 0.25 (deg/s) -->
            <bias_mean>0.0</bias_mean>
            <bias_stddev>0.0</bias_stddev>
          </rate>
          <accel>
            <!-- not used in the plugin and real robot, hence using tutorial values -->
            <mean>0.0</mean>
            <stddev>1.7e-2</stddev>
            <bias_mean>0.1</bias_mean>
            <bias_stddev>0.001</bias_stddev>
          </accel>
        </noise>
      </imu>
    </sensor>
  </gazebo>
  <gazebo>
    <plugin filename="libgazebo_ros_kobuki.so" name="kobuki_controller">
      <publish_tf>1</publish_tf>
      <left_wheel_joint_name>wheel_left_joint</left_wheel_joint_name>
      <right_wheel_joint_name>wheel_right_joint</right_wheel_joint_name>
      <wheel_separation>.230</wheel_separation>
      <wheel_diameter>0.070</wheel_diameter>
      <torque>1.0</torque>
      <velocity_command_timeout>0.6</velocity_command_timeout>
      <cliff_sensor_left_name>cliff_sensor_left</cliff_sensor_left_name>
      <cliff_sensor_center_name>cliff_sensor_front</cliff_sensor_center_name>
      <cliff_sensor_right_name>cliff_sensor_right</cliff_sensor_right_name>
      <cliff_detection_threshold>0.04</cliff_detection_threshold>
      <bumper_name>bumpers</bumper_name>
      <imu_name>imu</imu_name>
    </plugin>
  </gazebo>
  <!-- hokuyo -->
  <gazebo reference="base_laser_link">
    <sensor name="head_hokuyo_sensor" type="ray">
      <pose>0 0 0 0 0 0</pose>
      <visualize>true</visualize>
      <update_rate>40</update_rate>
      <ray>
        <scan>
          <horizontal>
            <samples>720</samples>
            <resolution>1</resolution>
            <min_angle>-1.570796</min_angle>
            <max_angle>1.570796</max_angle>
          </horizontal>
        </scan>
        <range>
          <min>0.10</min>
          <max>60</max>
          <resolution>0.01</resolution>
        </range>
        <noise>
          <type>gaussian</type>
          <!-- Noise parameters based on published spec for Hokuyo laser
               achieving "+-30mm" accuracy at range < 10m.  A mean of 0.0m and
               stddev of 0.01m will put 99.7% of samples within 0.03m of the true
               reading. -->
          <mean>0.0</mean>
          <stddev>0.01</stddev>
        </noise>
      </ray>
      <plugin filename="libgazebo_ros_laser.so" name="gazebo_ros_head_hokuyo_controller">
        <topicName>base_scan</topicName>
        <frameName>base_laser_link</frameName>
      </plugin>
    </sensor>
  </gazebo>
  <!-- camera -->
  <gazebo reference="camera_link">
    <sensor name="rgbcamera" type="camera">
      <update_rate>30.0</update_rate>
      <camera name="head">
        <horizontal_fov>1.4</horizontal_fov>
        <image>
          <width>642</width>
          <height>362</height>
          <format>R8G8B8</format>
        </image>
        <clip>
          <near>0.02</near>
          <far>300</far>
        </clip>
        <noise>
          <type>gaussian</type>
          <!-- Noise is sampled independently per pixel on each frame.
               That pixel's noise value is added to each of its color
               channels, which at that point lie in the range [0,1]. -->
          <mean>0.0</mean>
          <stddev>0.007</stddev>
        </noise>
      </camera>
      <plugin filename="libgazebo_ros_camera.so" name="camera_controller">
        <alwaysOn>true</alwaysOn>
        <updateRate>0.0</updateRate>
        <cameraName>rgbcamera</cameraName>
        <imageTopicName>image_raw</imageTopicName>
        <cameraInfoTopicName>camera_info</cameraInfoTopicName>
        <frameName>camera_link</frameName>
        <hackBaseline>0.07</hackBaseline>
        <distortionK1>0.0</distortionK1>
        <distortionK2>0.0</distortionK2>
        <distortionK3>0.0</distortionK3>
        <distortionT1>0.0</distortionT1>
        <distortionT2>0.0</distortionT2>
      </plugin>
    </sensor>
  </gazebo>
</robot>

